Traceback (most recent call last):
  File "main.py", line 93, in <module>
    test_losses['batch'].append(test_batch_loss)
KeyError: 'batch'